{"cert_user_id": "arthurlutz@github", "next_comment_id": 3, "comment": {"1604064727_mirrored_thesoftwarejedi_github": [{"comment_id": 1, "body": "same here\n", "added": 1421428150, "modified": 1421428150, "source_link": "https://github.com/HelloZeroNet/ZeroNet/issues/2#issuecomment-70314449", "source_type": "github"}], "1604064770_mirrored_arthurlutz_github": [{"comment_id": 2, "body": "Then I have a bunch of \n\n```\nTraceback (most recent call last):\n  File \"/usr/lib/python2.7/dist-packages/gevent/greenlet.py\", line 327, in run\n    result = self._run(*self.args, **self.kwargs)\n  File \"/home/arthur/local/ZeroNet/src/Worker/Worker.py\", line 34, in downloader\n    buff = self.peer.getFile(task[\"site\"].address, task[\"inner_path\"])\n  File \"/home/arthur/local/ZeroNet/src/Peer/Peer.py\", line 87, in getFile\n    back = self.sendCmd(\"getFile\", {\"site\": site, \"inner_path\": inner_path, \"location\": location}) # Get file content from last location\n  File \"/home/arthur/local/ZeroNet/src/Peer/Peer.py\", line 71, in sendCmd\n    self.onConnectionError()\n  File \"/home/arthur/local/ZeroNet/src/Peer/Peer.py\", line 137, in onConnectionError\n    self.remove()\n  File \"/home/arthur/local/ZeroNet/src/Peer/Peer.py\", line 127, in remove\n    del(self.site.peers[self.key])\nKeyError: '104.156.231.236:15441'\n<Greenlet at 0x7f92ea96a050: <bound method Worker.downloader of <Worker.Worker.Worker instance at 0x7f92ea95dd88>>> failed with KeyError\n\n[09:48:56] Site:1EU1tb..E4Vr Can't update content.json\n```\n", "added": 1422251365, "modified": 1422251365, "source_link": "https://github.com/HelloZeroNet/ZeroNet/issues/35#issuecomment-71429433", "source_type": "github"}]}, "next_topic_id": 5, "topic": [{"topic_id": 1604064748, "title": "If miniupnpc -e ZeroNet fails, try without -e", "body": "My version of miniupnpc doesn't understand \"-e ZeroNet\" but the rest of the command is right. Maybe there could be a test or a try/except to do it without the -e option.\n", "parent_topic_uri": "1604062980_users_1Cy3ntkN2GN9MH6EaW6eHpi4YoRS2nK5Di", "added": 1421427125, "modified": 1421832584, "source_link": "https://github.com/HelloZeroNet/ZeroNet/issues/19", "source_type": "github"}, {"topic_id": 1604064751, "title": "Detect installed upnpc", "body": "I think the README should recommend installing upnpc via packages (for example apt-get install miniupnc) and then ZeroNet could check if upnpc is in the path instead of having to explicitly use --upnpc option.\n", "parent_topic_uri": "1604062980_users_1Cy3ntkN2GN9MH6EaW6eHpi4YoRS2nK5Di", "added": 1421427199, "modified": 1424889708, "source_link": "https://github.com/HelloZeroNet/ZeroNet/issues/20", "source_type": "github"}, {"topic_id": 1604064770, "title": "NameError: global name 'wraper_key' is not defined", "body": "After git pull : \n\n```\nTraceback (most recent call last):\n  File \"/usr/lib/python2.7/dist-packages/gevent/pywsgi.py\", line 508, in handle_one_response\n    self.run_application()\n  File \"/home/arthur/local/ZeroNet/src/Ui/UiServer.py\", line 21, in run_application\n    self.ws_handler.run_application()\n  File \"/home/arthur/local/ZeroNet/src/lib/geventwebsocket/handler.py\", line 81, in run_application\n    self.run_websocket()\n  File \"/home/arthur/local/ZeroNet/src/lib/geventwebsocket/handler.py\", line 57, in run_websocket\n    self.application(self.environ, lambda s, h: [])\n  File \"/home/arthur/local/ZeroNet/src/Ui/UiServer.py\", line 49, in handleRequest\n    return self.ui_request.route(path)\n  File \"/home/arthur/local/ZeroNet/src/Ui/UiRequest.py\", line 41, in route\n    return self.actionWebsocket()\n  File \"/home/arthur/local/ZeroNet/src/Ui/UiRequest.py\", line 239, in actionWebsocket\n    self.log.error(\"Wrapper key not found: %s\" % wraper_key)\nNameError: global name 'wraper_key' is not defined\n```\n", "parent_topic_uri": "1604062980_users_1Cy3ntkN2GN9MH6EaW6eHpi4YoRS2nK5Di", "added": 1422251332, "modified": 1435249328, "source_link": "https://github.com/HelloZeroNet/ZeroNet/issues/35", "source_type": "github"}, {"topic_id": 1604064796, "title": "upnp python has some errors (NameError: global name 'SocketError' first)", "body": "```\n src.File.FileServer UpnpPunch run error: NameError: global name 'SocketError' is not defined in FileServer.py line 50 > UpnpPunch.py line 176 > UpnpPunch.py line 40\n```\n\nreplacing SocketError by socket.error gets us to another error : \n\n```\nsrc.File.FileServer UpnpPunch run error: UnboundLocalError: local variable 'data' referenced before assignment in FileServer.py line 50 > UpnpPunch.py line 176 > UpnpPunch.py line 44\n```\n\nadding return to the except block gets us another error : \n\n```\nsrc.File.FileServer UpnpPunch run error: TypeError: expected string or buffer in FileServer.py line 50 > UpnpPunch.py line 176 > UpnpPunch.py line 52 > re.py line 177\n```\n\nI gave up there... \n", "parent_topic_uri": "1604062980_users_1Cy3ntkN2GN9MH6EaW6eHpi4YoRS2nK5Di", "added": 1424943686, "modified": 1425767805, "source_link": "https://github.com/HelloZeroNet/ZeroNet/issues/54", "source_type": "github"}]}