{"cert_user_id": "jurf@github", "next_topic_id": 2, "topic": [{"topic_id": 1604064964, "title": "Problems on Arch Linux", "body": "(I have used the AUR package, but that shouldn't change anything)\n\nHey. So I wanted to try out zeronet, but after installing it I found out that there's `#!/usr/bin/env python` at the start of the scripts, which default to Python 3 on Arch Linux, resulting in a while bunch of error. Any idea how to fix it without `sed`ing?\n\nThanks.\n", "parent_topic_uri": "1604062980_users_1Cy3ntkN2GN9MH6EaW6eHpi4YoRS2nK5Di", "added": 1445143079, "modified": 1445354362, "source_link": "https://github.com/HelloZeroNet/ZeroNet/issues/187", "source_type": "github"}], "next_comment_id": 3, "comment": {"1604064964_mirrored_jurf_github": [{"comment_id": 1, "body": "```\n$ python2 /usr/bin/zeronet.py\n- Starting ZeroNet...\nTraceback (most recent call last):\n  File \"/usr/bin/zeronet.py\", line 14, in main\n    import main\nImportError: No module named main\nTraceback (most recent call last):\n  File \"/usr/bin/zeronet.py\", line 54, in <module>\n    main()\n  File \"/usr/bin/zeronet.py\", line 40, in main\n    traceback.print_exc(file=open(\"log/error.log\", \"a\"))\nIOError: [Errno 2] No such file or directory: 'log/error.log'\n```\n", "added": 1445353079, "modified": 1445353079, "source_link": "https://github.com/HelloZeroNet/ZeroNet/issues/187#issuecomment-149648010", "source_type": "github"}, {"comment_id": 2, "body": "Hm, works great, thanks. Looks like the package is faulty.\n", "added": 1445354362, "modified": 1445354362, "source_link": "https://github.com/HelloZeroNet/ZeroNet/issues/187#issuecomment-149653397", "source_type": "github"}]}}