{
    "issues": [
        {
            "title": "Error when trying to start the server on Debian 10",
            "body": "When doing `python start_server.py` i get\n\n`Traceback (most recent call last):\n  File \"start_server.py\", line 1, in <module>\n    from config import zeronet_directory\n  File \"/tmp/zeromail-to-email-client-transport/config.py\", line 14, in <module>\n    import Config\nModuleNotFoundError: No module named 'Config'`",
            "date_added": 1578868706771,
            "open": 1,
            "reopened": 0,
            "tags": "error",
            "id": 0
        }
    ],
    "next_issue_id": 1
}