{"cert_user_id": "Vertux@github", "next_topic_id": 2, "topic": [{"topic_id": 1604065934, "title": "I get an \"Unhandled exception\" when I start zeronet in a VM (Ubuntu Server v16.10)  ", "body": "If I try to run the current zeronet version in a VM with Ubuntu v16.10 I get this error:\r\n\r\n```\r\npython zeronet.py --ui_ip \"*\" --ui_password ****deleted****\r\n- Starting ZeroNet...\r\n[10:50:33] - OpenSSL loaded, version: 01000207F\r\n[10:50:33] - Version: 0.5.5 r2089, Python 2.7.12+ (default, Sep 17 2016, 12:08:02)\r\n[GCC 6.2.0 20160914], Gevent: 1.1.1\r\n[10:50:33] - Creating FileServer....\r\n[10:50:33] TorManager Connecting to Tor Controller 127.0.0.1:9051\r\n[10:50:33] TorManager Tor controller connect error: error: [Errno 111] Connection refused in TorManager.py line 165 > _socket2.py line 228\r\n[10:50:33] TorManager Starting self-bundled Tor, due to Tor proxy port 127.0.0.1:9050 check error: No connection\r\n[10:50:33] - Creating UiServer....\r\n[10:50:33] - Removing old SSL certs...\r\n[10:50:33] - Starting servers....\r\n[10:50:33] Ui.UiServer --------------------------------------\r\n[10:50:33] Ui.UiServer Web interface: http://*:43110/\r\n[10:50:33] Ui.UiServer --------------------------------------\r\n[10:50:35] FileServer Checking port 15441 using portchecker.co...\r\n[10:50:36] FileServer [BAD :(] Port closed: Port 15441 is closed.\r\n[10:50:36] FileServer Trying to open port using UpnpPunch...\r\n[10:50:36] - Unhandled exception\r\nTraceback (most recent call last):\r\n  File \"/usr/lib/python2.7/dist-packages/gevent/greenlet.py\", line 534, in run\r\n    result = self._run(*self.args, **self.kwargs)\r\n  File \"/home/zero/zeronet/src/File/FileServer.py\", line 193, in checkSites\r\n    self.openport()\r\n  File \"/home/zero/zeronet/src/File/FileServer.py\", line 74, in openport\r\n    UpnpPunch.ask_to_open_port(self.port, 'ZeroNet', retries=3, protos=[\"TCP\"])\r\n  File \"/home/zero/zeronet/src/util/UpnpPunch.py\", line 325, in ask_to_open_port\r\n    protos=protos)\r\n  File \"/home/zero/zeronet/src/util/UpnpPunch.py\", line 304, in _communicate_with_igd\r\n    _orchestrate_soap_request(local_ip, port, fn, desc, protos)\r\n  File \"/home/zero/zeronet/src/util/UpnpPunch.py\", line 279, in _orchestrate_soap_request\r\n    idg_data = _collect_idg_data(ip)\r\n  File \"/home/zero/zeronet/src/util/UpnpPunch.py\", line 263, in _collect_idg_data\r\n    _retrieve_igd_profile(idg_data['location']))\r\n  File \"/home/zero/zeronet/src/util/UpnpPunch.py\", line 86, in _retrieve_igd_profile\r\n    return urllib2.urlopen(url.geturl(), timeout=5).read().decode('utf-8')\r\n  File \"/usr/lib/python2.7/urllib2.py\", line 154, in urlopen\r\n    return opener.open(url, data, timeout)\r\n  File \"/usr/lib/python2.7/urllib2.py\", line 435, in open\r\n    response = meth(req, response)\r\n  File \"/usr/lib/python2.7/urllib2.py\", line 548, in http_response\r\n    'http', request, response, code, msg, hdrs)\r\n  File \"/usr/lib/python2.7/urllib2.py\", line 473, in error\r\n    return self._call_chain(*args)\r\n  File \"/usr/lib/python2.7/urllib2.py\", line 407, in _call_chain\r\n    result = func(*args)\r\n  File \"/usr/lib/python2.7/urllib2.py\", line 556, in http_error_default\r\n    raise HTTPError(req.get_full_url(), code, msg, hdrs, fp)\r\nHTTPError: HTTP Error 404: Not Found\r\nTraceback (most recent call last):\r\n  File \"/usr/lib/python2.7/dist-packages/gevent/greenlet.py\", line 534, in run\r\n    result = self._run(*self.args, **self.kwargs)\r\n  File \"/home/zero/zeronet/src/File/FileServer.py\", line 193, in checkSites\r\n    self.openport()\r\n  File \"/home/zero/zeronet/src/File/FileServer.py\", line 74, in openport\r\n    UpnpPunch.ask_to_open_port(self.port, 'ZeroNet', retries=3, protos=[\"TCP\"])\r\n  File \"/home/zero/zeronet/src/util/UpnpPunch.py\", line 325, in ask_to_open_port\r\n    protos=protos)\r\n  File \"/home/zero/zeronet/src/util/UpnpPunch.py\", line 304, in _communicate_with_igd\r\n    _orchestrate_soap_request(local_ip, port, fn, desc, protos)\r\n  File \"/home/zero/zeronet/src/util/UpnpPunch.py\", line 279, in _orchestrate_soap_request\r\n    idg_data = _collect_idg_data(ip)\r\n  File \"/home/zero/zeronet/src/util/UpnpPunch.py\", line 263, in _collect_idg_data\r\n    _retrieve_igd_profile(idg_data['location']))\r\n  File \"/home/zero/zeronet/src/util/UpnpPunch.py\", line 86, in _retrieve_igd_profile\r\n    return urllib2.urlopen(url.geturl(), timeout=5).read().decode('utf-8')\r\n  File \"/usr/lib/python2.7/urllib2.py\", line 154, in urlopen\r\n    return opener.open(url, data, timeout)\r\n  File \"/usr/lib/python2.7/urllib2.py\", line 435, in open\r\n    response = meth(req, response)\r\n  File \"/usr/lib/python2.7/urllib2.py\", line 548, in http_response\r\n    'http', request, response, code, msg, hdrs)\r\n  File \"/usr/lib/python2.7/urllib2.py\", line 473, in error\r\n    return self._call_chain(*args)\r\n  File \"/usr/lib/python2.7/urllib2.py\", line 407, in _call_chain\r\n    result = func(*args)\r\n  File \"/usr/lib/python2.7/urllib2.py\", line 556, in http_error_default\r\n    raise HTTPError(req.get_full_url(), code, msg, hdrs, fp)\r\nurllib2.HTTPError: HTTP Error 404: Not Found\r\n```", "parent_topic_uri": "1604062980_users_1Cy3ntkN2GN9MH6EaW6eHpi4YoRS2nK5Di", "added": 1495778833, "modified": 1495783378, "source_link": "https://github.com/HelloZeroNet/ZeroNet/issues/953", "source_type": "github"}]}