{"cert_user_id": "javenisme@github", "next_topic_id": 2, "topic": [{"topic_id": 1604066051, "title": "run \"ZeroNet siteCreate\" on macOS sierra occur error", "body": "\u279c  MacOS ./ZeroNet siteCreate\r\n- Starting ZeroNet...\r\n- OpenSSL loaded, version: 0009081DF\r\n- Version: 0.5.4 r2054, Python 2.7.13 (v2.7.13:a06454b1afa1, Dec 17 2016, 12:39:47)\r\n[GCC 4.2.1 (Apple Inc. build 5666) (dot 3)], Gevent: 1.2.1\r\n- Generating new privatekey...\r\n- ----------------------------------------------------------------------\r\n- Site private key: 5J2vjCYnidUjbigbWjFZucuf64gWfjxt5Q8ShSoAH6XMuPwXpQF\r\n-                   !!! ^ Save it now, required to modify the site ^ !!!\r\n- Site address:     13JfSkzJG8Tms8GsbYoVX6FhRvKdHHpRFo\r\n- ----------------------------------------------------------------------\r\n? Have you secured your private key? (yes, no) > yes\r\n- Creating directory structure...\r\n- Creating content.json...\r\nSite:13JfSk..pRFo Content.json not exist: /Users/jobs/Library/Application Support/ZeroNet/data/13JfSkzJG8Tms8GsbYoVX3FhRvKdHHpRFo/content.json\r\nSite:13JfSk..pRFo File content.json not exist yet, loading default values...\r\nSite:13JfSk..pRFo Opening site data directory: /Users/jobs/Library/Application Support/ZeroNet/data/13JfSkzJG8Tms8GsbYoVX3FhRvKdHHpRFo/...\r\nSite:13JfSk..pRFo - index.html (SHA512: 47ad6e3c1cd06668156ea8409c595002bc523537eef00c5d3b2a6336557a9b5b)\r\nSite:13JfSk..pRFo Adding timestamp and sha512sums to new content.json...\r\nSite:13JfSk..pRFo Verifying private key...\r\nSite:13JfSk..pRFo Correct 13JfSkzJG8Tms8GsbYoVX3FhRvKdHHpRFo in valid signers: ['13JfSkzJG8Tms8GsbYoVX3FhRvKdHHpRFo']\r\nSite:13JfSk..pRFo Signing content.json...\r\nSite:13JfSk..pRFo Saving to content.json...\r\nSite:13JfSk..pRFo File content.json signed!\r\n- Site created!\r\n- Unhandled exception\r\nNone\r\nTraceback (most recent call last):\r\n  File \"gevent/hub.pyo\", line 857, in switch\r\n  File \"/Applications/ZeroNet.app/Contents/Resources/boot.py\", line 137, in signalHandler\r\n    raise ExitCommand()\r\n__main__.ExitCommand\r\n- Unhandled exception\r\nNone\r\nTraceback (most recent call last):\r\n  File \"/Applications/ZeroNet.app/Contents/Resources/__boot__.py\", line 81, in <module>\r\n    _run()\r\n  File \"/Applications/ZeroNet.app/Contents/Resources/__boot__.py\", line 66, in _run\r\n    exec(compile(source, path, 'exec'), globals(), globals())\r\n  File \"/Applications/ZeroNet.app/Contents/Resources/boot.py\", line 179, in <module>\r\n    gui()\r\n  File \"/Applications/ZeroNet.app/Contents/Resources/boot.py\", line 106, in gui\r\n    time.sleep(0.1)\r\n  File \"gevent/hub.pyo\", line 169, in sleep\r\n  File \"gevent/hub.pyo\", line 651, in wait\r\n  File \"gevent/hub.pyo\", line 899, in get\r\n  File \"gevent/hub.pyo\", line 630, in switch\r\ngevent.hub.LoopExit: ('This operation would block forever', <Hub at 0x1057ce230 select pending=0 ref=0>)\r\n2017-07-25 11:17:28.081 ZeroNet[87824:11603434] ZeroNet Error\r\n2017-07-25 11:17:28.081 ZeroNet[87824:11603434] ZeroNet Error", "parent_topic_uri": "1604062980_users_1Cy3ntkN2GN9MH6EaW6eHpi4YoRS2nK5Di", "added": 1500942029, "modified": 1501276624, "source_link": "https://github.com/HelloZeroNet/ZeroNet/issues/1046", "source_type": "github"}]}